Workbook
Name UPDATE: 'Data Sheet'!$E$1

Sheet Profit & Loss
A1: ='Data Sheet'!B1 -> RELIANCE INDUSTRIES LTD | H1: =UPDATE | M1: SCREENER.IN
A3: Narration | B3: ='Data Sheet'!B16 -> 42825 | C3: ='Data Sheet'!C16 -> 43190 | D3: ='Data Sheet'!D16 -> 43555 | E3: ='Data Sheet'!E16 -> 43921 | F3: ='Data Sheet'!F16 -> 44286 | G3: ='Data Sheet'!G16 -> 44651 | H3: ='Data Sheet'!H16 -> 45016 | I3: ='Data Sheet'!I16 -> 45382 | ... K3: ='Data Sheet'!K16 -> 46112 | L3: Trailing | M3: Best Case | N3: Worst Case
A4: Sales | B4: ='Data Sheet'!B17 -> 303954 | C4: ='Data Sheet'!C17 -> 390823 | D4: ='Data Sheet'!D17 -> 568337 | E4: ='Data Sheet'!E17 -> 596679 | F4: ='Data Sheet'!F17 -> 466307 | G4: ='Data Sheet'!G17 -> 694673 | H4: ='Data Sheet'!H17 -> 876396 | I4: ='Data Sheet'!I17 -> 899041 | ... K4: ='Data Sheet'!K17 -> 1057219 | L4: =SUM(#REF!) -> #REF! | M4: =$K4+M23*K4 -> 1125433.4 | N4: =$K4+N23*L4 -> #REF!
A5: Expenses | B5: =SUM('Data Sheet'!B18,'Data Sheet'!B20:B24, -1*'Data Sheet'!B19) -> 257647 | C5: =SUM('Data Sheet'!C18,'Data Sheet'!C20:C24, -1*'Data Sheet'!C19) -> 326508 | D5: =SUM('Data Sheet'!D18,'Data Sheet'!D20:D24, -1*'Data Sheet'!D19) -> 484087 | E5: =SUM('Data Sheet'!E18,'Data Sheet'!E20:E24, -1*'Data Sheet'!E19) -> 507413 | F5: =SUM('Data Sheet'!F18,'Data Sheet'!F20:F24, -1*'Data Sheet'!F19) -> 385517 | G5: =SUM('Data Sheet'!G18,'Data Sheet'!G20:G24, -1*'Data Sheet'!G19) -> 586092 | H5: =SUM('Data Sheet'!H18,'Data Sheet'!H20:H24, -1*'Data Sheet'!H19) -> 734078 | I5: =SUM('Data Sheet'!I18,'Data Sheet'!I20:I24, -1*'Data Sheet'!I19) -> 736543 | ... K5: =SUM('Data Sheet'!K18,'Data Sheet'!K20:K24, -1*'Data Sheet'!K19) -> 878270 | L5: =SUM(#REF!) -> #REF! | M5: =M4-M6 -> #REF! | N5: =N4-N6 -> #REF!
A6: Operating Profit | B6: =B4-B5 -> 46307 | C6: =C4-C5 -> 64315 | D6: =D4-D5 -> 84250 | E6: =E4-E5 -> 89266 | F6: =F4-F5 -> 80790 | G6: =G4-G5 -> 108581 | H6: =H4-H5 -> 142318 | I6: =I4-I5 -> 162498 | ... K6: =K4-K5 -> 178949 | L6: =SUM(#REF!) -> #REF! | M6: =M4*M24 -> #REF! | N6: =N4*N24 -> #REF!
A7: Other Income | B7: ='Data Sheet'!B25 -> 9222 | C7: ='Data Sheet'!C25 -> 9869 | D7: ='Data Sheet'!D25 -> 8406 | E7: ='Data Sheet'!E25 -> 8570 | F7: ='Data Sheet'!F25 -> 22432 | G7: ='Data Sheet'!G25 -> 19600 | H7: ='Data Sheet'!H25 -> 12020 | I7: ='Data Sheet'!I25 -> 15792 | ... K7: ='Data Sheet'!K25 -> 28962 | L7: =SUM(#REF!) -> #REF! | M7: 0 | N7: 0
A8: Depreciation | B8: ='Data Sheet'!B26 -> 11646 | C8: ='Data Sheet'!C26 -> 16706 | D8: ='Data Sheet'!D26 -> 20934 | E8: ='Data Sheet'!E26 -> 22203 | F8: ='Data Sheet'!F26 -> 26572 | G8: ='Data Sheet'!G26 -> 29782 | H8: ='Data Sheet'!H26 -> 40303 | I8: ='Data Sheet'!I26 -> 50832 | ... K8: ='Data Sheet'!K26 -> 57688 | L8: =SUM(#REF!) -> #REF! | M8: =+$L8 -> #REF! | N8: =+$L8 -> #REF!
A9: Interest | B9: ='Data Sheet'!B27 -> 3849 | C9: ='Data Sheet'!C27 -> 8052 | D9: ='Data Sheet'!D27 -> 16495 | E9: ='Data Sheet'!E27 -> 22027 | F9: ='Data Sheet'!F27 -> 21189 | G9: ='Data Sheet'!G27 -> 14584 | H9: ='Data Sheet'!H27 -> 19571 | I9: ='Data Sheet'!I27 -> 23118 | ... K9: ='Data Sheet'!K27 -> 27061 | L9: =SUM(#REF!) -> #REF! | M9: =+$L9 -> #REF! | N9: =+$L9 -> #REF!
A10: Profit before tax | B10: ='Data Sheet'!B28 -> 40034 | C10: ='Data Sheet'!C28 -> 49426 | D10: ='Data Sheet'!D28 -> 55227 | E10: ='Data Sheet'!E28 -> 53606 | F10: ='Data Sheet'!F28 -> 55461 | G10: ='Data Sheet'!G28 -> 83815 | H10: ='Data Sheet'!H28 -> 94464 | I10: ='Data Sheet'!I28 -> 104340 | ... K10: ='Data Sheet'!K28 -> 123162 | L10: =SUM(#REF!) -> #REF! | M10: =M6+M7-SUM(M8:M9) -> #REF! | N10: =N6+N7-SUM(N8:N9) -> #REF!
A11: Tax | B11: ='Data Sheet'!B29 -> 10201 | C11: ='Data Sheet'!C29 -> 13346 | D11: ='Data Sheet'!D29 -> 15390 | E11: ='Data Sheet'!E29 -> 13726 | F11: ='Data Sheet'!F29 -> 1722 | G11: ='Data Sheet'!G29 -> 15970 | H11: ='Data Sheet'!H29 -> 20376 | I11: ='Data Sheet'!I29 -> 25707 | ... K11: ='Data Sheet'!K29 -> 27552 | L11: =SUM(#REF!) -> #REF! | M11: =IF($L10>0,$L11/$L10,0) -> #REF! | N11: =IF($L10>0,$L11/$L10,0) -> #REF!
A12: Net profit | B12: ='Data Sheet'!B30 -> 29901 | C12: ='Data Sheet'!C30 -> 36075 | D12: ='Data Sheet'!D30 -> 39588 | E12: ='Data Sheet'!E30 -> 39354 | F12: ='Data Sheet'!F30 -> 49128 | G12: ='Data Sheet'!G30 -> 60705 | H12: ='Data Sheet'!H30 -> 66702 | I12: ='Data Sheet'!I30 -> 69621 | ... K12: ='Data Sheet'!K30 -> 80775 | L12: =SUM(#REF!) -> #REF! | M12: =M10-M11*M10 -> #REF! | N12: =N10-N11*N10 -> #REF!
A13: EPS | B13: =IF('Data Sheet'!B93>0,B12/'Data Sheet'!B93,0) -> 21.55462 | C13: =IF('Data Sheet'!C93>0,C12/'Data Sheet'!C93,0) -> 26.694737 | D13: =IF('Data Sheet'!D93>0,D12/'Data Sheet'!D93,0) -> 29.275435 | E13: =IF('Data Sheet'!E93>0,E12/'Data Sheet'!E93,0) -> 29.100024 | F13: =IF('Data Sheet'!F93>0,F12/'Data Sheet'!F93,0) -> 38.747841 | G13: =IF('Data Sheet'!G93>0,G12/'Data Sheet'!G93,0) -> 44.867626 | H13: =IF('Data Sheet'!H93>0,H12/'Data Sheet'!H93,0) -> 49.294963 | I13: =IF('Data Sheet'!I93>0,I12/'Data Sheet'!I93,0) -> 51.451439 | ... K13: =IF('Data Sheet'!K93>0,K12/'Data Sheet'!K93,0) -> 59.689636 | L13: =IF('Data Sheet'!$B6>0,'Profit & Loss'!L12/'Data Sheet'!$B6,0) -> #REF! | M13: =IF('Data Sheet'!$B6>0,'Profit & Loss'!M12/'Data Sheet'!$B6,0) -> #REF! | N13: =IF('Data Sheet'!$B6>0,'Profit & Loss'!N12/'Data Sheet'!$B6,0) -> #REF!
A14: Price to earning | B14: =IF(B15>0,B15/B13,"") -> 13.922305 | C14: =IF(C15>0,C15/C13,"") -> 15.024685 | D14: =IF(D15>0,D15/D13,"") -> 21.158695 | E14: =IF(E15>0,E15/E13,"") -> 17.390363 | F14: =IF(F15>0,F15/F13,"") -> 23.711773 | G14: =IF(G15>0,G15/G13,"") -> 26.935011 | H14: =IF(H15>0,H15/H13,"") -> 21.690046 | I14: =IF(I15>0,I15/I13,"") -> 28.878687 | ... K14: =IF(K15>0,K15/K13,"") -> 22.514796 | L14: =IF(L13>0,L15/L13,0) -> #REF! | M14: =M25 -> #REF! | N14: =N25 -> #REF!
A15: Price | B15: ='Data Sheet'!B90 -> 300.09 | C15: ='Data Sheet'!C90 -> 401.08 | D15: ='Data Sheet'!D90 -> 619.43 | E15: ='Data Sheet'!E90 -> 506.06 | F15: ='Data Sheet'!F90 -> 918.78 | G15: ='Data Sheet'!G90 -> 1208.51 | H15: ='Data Sheet'!H90 -> 1069.21 | I15: ='Data Sheet'!I90 -> 1485.85 | ... K15: ='Data Sheet'!K90 -> 1343.9 | L15: ='Data Sheet'!B8 -> 1410.7 | M15: =M13*M14 -> #REF! | N15: =N13*N14 -> #REF!
A17: RATIOS:
A18: Dividend Payout | B18: =IF('Data Sheet'!B30>0, 'Data Sheet'!B31/'Data Sheet'!B30, 0) -> 0.10885589 | C18: =IF('Data Sheet'!C30>0, 'Data Sheet'!C31/'Data Sheet'!C30, 0) -> 0.098494802 | D18: =IF('Data Sheet'!D30>0, 'Data Sheet'!D31/'Data Sheet'!D30, 0) -> 0.097299687 | E18: =IF('Data Sheet'!E30>0, 'Data Sheet'!E31/'Data Sheet'!E30, 0) -> 0.10469965 | F18: =IF('Data Sheet'!F30>0, 'Data Sheet'!F31/'Data Sheet'!F30, 0) -> 0.091831542 | G18: =IF('Data Sheet'!G30>0, 'Data Sheet'!G31/'Data Sheet'!G30, 0) -> 0.089152459 | H18: =IF('Data Sheet'!H30>0, 'Data Sheet'!H31/'Data Sheet'!H30, 0) -> 0.091292615 | I18: =IF('Data Sheet'!I30>0, 'Data Sheet'!I31/'Data Sheet'!I30, 0) -> 0.097183321 | ... K18: =IF('Data Sheet'!K30>0, 'Data Sheet'!K31/'Data Sheet'!K30, 0) -> 0.10051625
A19: OPM | B19: =IF(B6>0,B6/B4,0) -> 0.15234871 | C19: =IF(C6>0,C6/C4,0) -> 0.16456299 | D19: =IF(D6>0,D6/D4,0) -> 0.14823951 | E19: =IF(E6>0,E6/E4,0) -> 0.14960473 | F19: =IF(F6>0,F6/F4,0) -> 0.17325496 | G19: =IF(G6>0,G6/G4,0) -> 0.1563052 | H19: =IF(H6>0,H6/H4,0) -> 0.16239006 | I19: =IF(I6>0,I6/I4,0) -> 0.18074593 | ... L19: =IF(L6>0,L6/L4,0) -> #REF!
G22: TRENDS: | H22: 10 YEARS | I22: 7 YEARS | J22: 5 YEARS | K22: 3 YEARS | L22: RECENT | M22: BEST | N22: WORST
G23: Sales Growth | H23: =IF(B4=0,"",POWER($K4/B4,1/9)-1) -> 0.14855233 | I23: =IF(D4=0,"",POWER($K4/D4,1/7)-1) -> 0.092718844 | J23: =IF(F4=0,"",POWER($K4/F4,1/5)-1) -> 0.17787337 | K23: =IF(H4=0,"",POWER($K4/H4, 1/3)-1) -> 0.06452253 | L23: =IF(ISERROR(MAX(IF(J4=0,"",(K4-J4)/J4),IF(K4=0,"",(L4-K4)/K4))),"",MAX(IF(J4=0,"",(K4-J4)/J4),IF(K4=0,"",(L4-K4)/K4))) | M23: =MAX(K23:L23) -> 0.06452253 | N23: =MIN(H23:L23) -> 0.06452253
G24: OPM | H24: =IF(SUM(B4:$K$4)=0,"",SUMPRODUCT(B19:$K$19,B4:$K$4)/SUM(B4:$K$4)) -> 0.16473459 | I24: =IF(SUM(E4:$K$4)=0,"",SUMPRODUCT(E19:$K$19,E4:$K$4)/SUM(E4:$K$4)) -> 0.16711281 | J24: =IF(SUM(G4:$K$4)=0,"",SUMPRODUCT(G19:$K$19,G4:$K$4)/SUM(G4:$K$4)) -> 0.16880153 | K24: =IF(SUM(I4:$K$4)=0, "", SUMPRODUCT(I19:$K$19,I4:$K$4)/SUM(I4:$K$4)) -> 0.17370028 | L24: =L19 -> #REF! | M24: =MAX(K24:L24) -> #REF! | N24: =MIN(H24:L24) -> #REF!
G25: Price to Earning | H25: =IF(ISERROR(AVERAGEIF(B14:$L14,">0")),"",AVERAGEIF(B14:$L14,">0")) -> 21.600118 | I25: =IF(ISERROR(AVERAGEIF(E14:$L14,">0")),"",AVERAGEIF(E14:$L14,">0")) -> 23.699356 | J25: =IF(ISERROR(AVERAGEIF(G14:$L14,">0")),"",AVERAGEIF(G14:$L14,">0")) -> 24.958671 | K25: =IF(ISERROR(AVERAGEIF(I14:$L14,">0")),"",AVERAGEIF(I14:$L14,">0")) -> 25.389433 | L25: =L14 -> #REF! | M25: =MAX(K25:L25) -> #REF! | N25: =MIN(H25:L25) -> #REF!

Sheet Data Sheet
A1: COMPANY NAME | B1: RELIANCE INDUSTRIES LTD | D1: SALES | E1: =IF(B2<>B3, "A NEW VERSION OF THE WORKSHEET IS AVAILABLE", "")
A2: LATEST VERSION | B2: 2.1 | E2: PLEASE DO NOT MAKE ANY CHANGES TO THIS SHEET
A3: CURRENT VERSION | B3: 2.1
A5: META
A6: Number of shares | B6: =IF(B9>0, B9/B8, 0) -> 1353.2535
A7: Face Value | B7: 10
A8: Current Price | B8: 1410.7
A9: Market Capitalization | B9: 1909034.7
A15: PROFIT & LOSS
A16: Report Date | B16: 42825 | C16: 43190 | D16: 43555 | E16: 43921 | F16: 44286 | G16: 44651 | H16: 45016 | I16: 45382 | J16: 45747 | K16: 46112
A17: Sales | B17: 303954 | C17: 390823 | D17: 568337 | E17: 596679 | F17: 466307 | G17: 694673 | H17: 876396 | I17: 899041 | J17: 962820 | K17: 1057219
A18: Raw Material Cost | B18: 217518 | C18: 276076 | D18: 399167 | E18: 410288 | F18: 301765 | G18: 494449 | H18: 618746 | I18: 590226 | J18: 644813 | K18: 698930
A19: Change in Inventory | B19: 5218 | C19: 8610 | D19: 4680 | E19: 5048 | F19: 9064 | G19: 21457 | H19: 30263 | I19: 4883 | J19: 15124 | K19: 10267
A20: Power and Fuel | B20: 11251 | C20: 14569 | D20: 17029 | E20: 15098 | F20: 13214 | G20: 17902 | H20: 25062 | I20: 22137 | J20: 23823
A21: Other Mfr. Exp | B21: 9909 | C21: 9691 | D21: 12198 | E21: 11434 | F21: 7687 | G21: 12174 | H21: 19658 | I21: 18276 | J21: 18358
A22: Employee Cost | B22: 8388 | C22: 9523 | D22: 12488 | E22: 14075 | F22: 14817 | G22: 18758 | H22: 24872 | I22: 25679 | J22: 28559 | K22: 30318
A23: Selling and admin | B23: 18520 | C23: 29111 | D23: 50221 | E23: 62622 | F23: 56154 | G23: 63513 | H23: 67369 | I23: 77292 | J23: 88760
A24: Other Expenses | B24: -2721 | C24: -3852 | D24: -2336 | E24: -1056 | F24: 944 | G24: 753 | H24: 8634 | I24: 7816 | J24: 8033 | K24: 159289
A25: Other Income | B25: 9222 | C25: 9869 | D25: 8406 | E25: 8570 | F25: 22432 | G25: 19600 | H25: 12020 | I25: 15792 | J25: 17824 | K25: 28962
A26: Depreciation | B26: 11646 | C26: 16706 | D26: 20934 | E26: 22203 | F26: 26572 | G26: 29782 | H26: 40303 | I26: 50832 | J26: 53136 | K26: 57688
A27: Interest | B27: 3849 | C27: 8052 | D27: 16495 | E27: 22027 | F27: 21189 | G27: 14584 | H27: 19571 | I27: 23118 | J27: 24269 | K27: 27061
A28: Profit before tax | B28: 40034 | C28: 49426 | D28: 55227 | E28: 53606 | F28: 55461 | G28: 83815 | H28: 94464 | I28: 104340 | J28: 106017 | K28: 123162
A29: Tax | B29: 10201 | C29: 13346 | D29: 15390 | E29: 13726 | F29: 1722 | G29: 15970 | H29: 20376 | I29: 25707 | J29: 25230 | K29: 27552
A30: Net profit | B30: 29901 | C30: 36075 | D30: 39588 | E30: 39354 | F30: 49128 | G30: 60705 | H30: 66702 | I30: 69621 | J30: 69648 | K30: 80775
A31: Dividend Amount | B31: 3254.9 | C31: 3553.2 | D31: 3851.9 | E31: 4120.35 | F31: 4511.5 | G31: 5412 | H31: 6089.4 | I31: 6766 | J31: 7442.6 | K31: 8119.2
A40: Quarters
A41: Report Date | B41: 45291 | C41: 45382 | D41: 45473 | E41: 45565 | F41: 45657 | G41: 45747 | H41: 45838 | I41: 45930 | J41: 46022 | K41: 46112
A42: Sales | B42: 225086 | C42: 236533 | D42: 231784 | E42: 231535 | F42: 239986 | G42: 261388 | H42: 243632 | I42: 254623 | J42: 264905 | K42: 294059
A43: Expenses | B43: 184430 | C43: 194017 | D43: 193019 | E43: 192477 | F43: 196197 | G43: 217556 | H43: 200727 | I43: 208738 | J43: 218887 | K43: 249918
A44: Other Income | B44: 3869 | C44: 4534 | D44: 3983 | E44: 4876 | F44: 4214 | G44: 4905 | H44: 15119 | I44: 4482 | J44: 4914 | K44: 4447
A45: Depreciation | B45: 12903 | C45: 13569 | D45: 13596 | E45: 12880 | F45: 13181 | G45: 13479 | H45: 13842 | I45: 14416 | J45: 14622 | K45: 14808
A46: Interest | B46: 5789 | C46: 5761 | D46: 5918 | E46: 6017 | F46: 6179 | G46: 6155 | H46: 7036 | I46: 6827 | J46: 6613 | K46: 6585
A47: Profit before tax | B47: 25833 | C47: 27720 | D47: 23234 | E47: 25037 | F47: 28643 | G47: 29103 | H47: 37146 | I47: 29124 | J47: 29697 | K47: 27195
A48: Tax | B48: 6345 | C48: 6577 | D48: 5786 | E48: 5936 | F48: 6839 | G48: 6669 | H48: 6465 | I48: 6978 | J48: 7530 | K48: 6579
A49: Net profit | B49: 17265 | C49: 18951 | D49: 15138 | E49: 16563 | F49: 18540 | G49: 19407 | H49: 26994 | I49: 18165 | J49: 18645 | K49: 16971
A50: Operating Profit | B50: 40656 | C50: 42516 | D50: 38765 | E50: 39058 | F50: 43789 | G50: 43832 | H50: 42905 | I50: 45885 | J50: 46018 | K50: 44141
A55: BALANCE SHEET
A56: Report Date | B56: 42825 | C56: 43190 | D56: 43555 | E56: 43921 | F56: 44286 | G56: 44651 | H56: 45016 | I56: 45382 | J56: 45747 | K56: 46112
A57: Equity Share Capital | B57: 2959 | C57: 5922 | D57: 5926 | E57: 6339 | F57: 6445 | G57: 6765 | H57: 6766 | I57: 6766 | J57: 13532 | K57: 13532
A58: Reserves | B58: 260750 | C58: 287584 | D58: 381186 | E58: 442827 | F58: 693727 | G58: 772720 | H58: 709106 | I58: 786715 | J58: 829668 | K58: 890498
...

Sheet Balance Sheet
A1: ='Profit & Loss'!A1 -> RELIANCE INDUSTRIES LTD | E1: =UPDATE | J1: SCREENER.IN
A3: Narration | B3: ='Data Sheet'!B56 -> 42825 | C3: ='Data Sheet'!C56 -> 43190 | D3: ='Data Sheet'!D56 -> 43555 | E3: ='Data Sheet'!E56 -> 43921 | F3: ='Data Sheet'!F56 -> 44286 | G3: ='Data Sheet'!G56 -> 44651 | H3: ='Data Sheet'!H56 -> 45016 | I3: ='Data Sheet'!I56 -> 45382 | ... K3: ='Data Sheet'!K56 -> 46112
A4: Equity Share Capital | B4: ='Data Sheet'!B57 -> 2959 | C4: ='Data Sheet'!C57 -> 5922 | D4: ='Data Sheet'!D57 -> 5926 | E4: ='Data Sheet'!E57 -> 6339 | F4: ='Data Sheet'!F57 -> 6445 | G4: ='Data Sheet'!G57 -> 6765 | H4: ='Data Sheet'!H57 -> 6766 | I4: ='Data Sheet'!I57 -> 6766 | ... K4: ='Data Sheet'!K57 -> 13532
A5: Reserves | B5: ='Data Sheet'!B58 -> 260750 | C5: ='Data Sheet'!C58 -> 287584 | D5: ='Data Sheet'!D58 -> 381186 | E5: ='Data Sheet'!E58 -> 442827 | F5: ='Data Sheet'!F58 -> 693727 | G5: ='Data Sheet'!G58 -> 772720 | H5: ='Data Sheet'!H58 -> 709106 | I5: ='Data Sheet'!I58 -> 786715 | ... K5: ='Data Sheet'!K58 -> 890498
A6: Borrowings | B6: ='Data Sheet'!B59 -> 217475 | C6: ='Data Sheet'!C59 -> 239843 | D6: ='Data Sheet'!D59 -> 307714 | E6: ='Data Sheet'!E59 -> 355133 | F6: ='Data Sheet'!F59 -> 278962 | G6: ='Data Sheet'!G59 -> 319158 | H6: ='Data Sheet'!H59 -> 451664 | I6: ='Data Sheet'!I59 -> 350719 | ... K6: ='Data Sheet'!K59 -> 398000
A7: Other Liabilities | B7: ='Data Sheet'!B60 -> 225618 | C7: ='Data Sheet'!C60 -> 277924 | D7: ='Data Sheet'!D60 -> 302804 | E7: ='Data Sheet'!E60 -> 358716 | F7: ='Data Sheet'!F60 -> 340931 | G7: ='Data Sheet'!G60 -> 399979 | H7: ='Data Sheet'!H60 -> 438346 | I7: ='Data Sheet'!I60 -> 610848 | ... K7: ='Data Sheet'!K60 -> 876110
A8: Total | B8: ='Data Sheet'!B61 -> 706802 | C8: ='Data Sheet'!C61 -> 811273 | D8: ='Data Sheet'!D61 -> 997630 | E8: ='Data Sheet'!E61 -> 1163015 | F8: ='Data Sheet'!F61 -> 1320065 | G8: ='Data Sheet'!G61 -> 1498622 | H8: ='Data Sheet'!H61 -> 1605882 | I8: ='Data Sheet'!I61 -> 1755048 | ... K8: ='Data Sheet'!K61 -> 2178140
A10: Net Block | B10: ='Data Sheet'!B62 -> 198526 | C10: ='Data Sheet'!C62 -> 403885 | D10: ='Data Sheet'!D62 -> 398374 | E10: ='Data Sheet'!E62 -> 532658 | F10: ='Data Sheet'!F62 -> 541258 | G10: ='Data Sheet'!G62 -> 627798 | H10: ='Data Sheet'!H62 -> 724805 | I10: ='Data Sheet'!I62 -> 779985 | ... K10: ='Data Sheet'!K62 -> 1170194
A11: Capital Work in Progress | B11: ='Data Sheet'!B63 -> 324837 | C11: ='Data Sheet'!C63 -> 187022 | D11: ='Data Sheet'!D63 -> 179463 | E11: ='Data Sheet'!E63 -> 109106 | F11: ='Data Sheet'!F63 -> 125953 | G11: ='Data Sheet'!G63 -> 172506 | H11: ='Data Sheet'!H63 -> 293752 | I11: ='Data Sheet'!I63 -> 338855 | ... K11: ='Data Sheet'!K63 -> 192287
A12: Investments | B12: ='Data Sheet'!B64 -> 82899 | C12: ='Data Sheet'!C64 -> 82862 | D12: ='Data Sheet'!D64 -> 235635 | E12: ='Data Sheet'!E64 -> 276767 | F12: ='Data Sheet'!F64 -> 364828 | G12: ='Data Sheet'!G64 -> 394264 | H12: ='Data Sheet'!H64 -> 235560 | I12: ='Data Sheet'!I64 -> 225672 | ... K12: ='Data Sheet'!K64 -> 248332
A13: Other Assets | B13: ='Data Sheet'!B65 -> 100540 | C13: ='Data Sheet'!C65 -> 137504 | D13: ='Data Sheet'!D65 -> 184158 | E13: ='Data Sheet'!E65 -> 244484 | F13: ='Data Sheet'!F65 -> 288026 | G13: ='Data Sheet'!G65 -> 304054 | H13: ='Data Sheet'!H65 -> 351765 | I13: ='Data Sheet'!I65 -> 410536 | ... K13: ='Data Sheet'!K65 -> 567327
A14: Total | B14: ='Data Sheet'!B66 -> 706802 | C14: ='Data Sheet'!C66 -> 811273 | D14: ='Data Sheet'!D66 -> 997630 | E14: ='Data Sheet'!E66 -> 1163015 | F14: ='Data Sheet'!F66 -> 1320065 | G14: ='Data Sheet'!G66 -> 1498622 | H14: ='Data Sheet'!H66 -> 1605882 | I14: ='Data Sheet'!I66 -> 1755048 | ... K14: ='Data Sheet'!K66 -> 2178140
A16: Working Capital | B16: =B13-B7 -> -125078 | C16: =C13-C7 -> -140420 | D16: =D13-D7 -> -118646 | E16: =E13-E7 -> -114232 | F16: =F13-F7 -> -52905 | G16: =G13-G7 -> -95925 | H16: =H13-H7 -> -86581 | I16: =I13-I7 -> -200312 | ... K16: =K13-K7 -> -308783
A17: Debtors | B17: ='Data Sheet'!B67 -> 8177 | C17: ='Data Sheet'!C67 -> 17555 | D17: ='Data Sheet'!D67 -> 30089 | E17: ='Data Sheet'!E67 -> 19656 | F17: ='Data Sheet'!F67 -> 19014 | G17: ='Data Sheet'!G67 -> 23640 | H17: ='Data Sheet'!H67 -> 28448 | I17: ='Data Sheet'!I67 -> 31628 | ... K17: ='Data Sheet'!K67 -> 58491
A18: Inventory | B18: ='Data Sheet'!B68 -> 48951 | C18: ='Data Sheet'!C68 -> 60837 | D18: ='Data Sheet'!D68 -> 67561 | E18: ='Data Sheet'!E68 -> 73903 | F18: ='Data Sheet'!F68 -> 81672 | G18: ='Data Sheet'!G68 -> 107778 | H18: ='Data Sheet'!H68 -> 140008 | I18: ='Data Sheet'!I68 -> 152770 | ... K18: ='Data Sheet'!K68 -> 166941
A20: Debtor Days | B20: =IF('Profit & Loss'!B4>0,'Balance Sheet'!B17/('Profit & Loss'!B4/365),0) -> 9.8192654 | C20: =IF('Profit & Loss'!C4>0,'Balance Sheet'!C17/('Profit & Loss'!C4/365),0) -> 16.395082 | D20: =IF('Profit & Loss'!D4>0,'Balance Sheet'!D17/('Profit & Loss'!D4/365),0) -> 19.323896 | E20: =IF('Profit & Loss'!E4>0,'Balance Sheet'!E17/('Profit & Loss'!E4/365),0) -> 12.023953 | F20: =IF('Profit & Loss'!F4>0,'Balance Sheet'!F17/('Profit & Loss'!F4/365),0) -> 14.883135 | G20: =IF('Profit & Loss'!G4>0,'Balance Sheet'!G17/('Profit & Loss'!G4/365),0) -> 12.421096 | H20: =IF('Profit & Loss'!H4>0,'Balance Sheet'!H17/('Profit & Loss'!H4/365),0) -> 11.847977 | I20: =IF('Profit & Loss'!I4>0,'Balance Sheet'!I17/('Profit & Loss'!I4/365),0) -> 12.840593 | ... K20: =IF('Profit & Loss'!K4>0,'Balance Sheet'!K17/('Profit & Loss'!K4/365),0) -> 20.193749
A21: Inventory Turnover | B21: =IF('Balance Sheet'!B18>0,'Profit & Loss'!B4/'Balance Sheet'!B18,0) -> 6.2093522 | C21: =IF('Balance Sheet'!C18>0,'Profit & Loss'!C4/'Balance Sheet'!C18,0) -> 6.4241005 | D21: =IF('Balance Sheet'!D18>0,'Profit & Loss'!D4/'Balance Sheet'!D18,0) -> 8.4122053 | E21: =IF('Balance Sheet'!E18>0,'Profit & Loss'!E4/'Balance Sheet'!E18,0) -> 8.073813 | F21: =IF('Balance Sheet'!F18>0,'Profit & Loss'!F4/'Balance Sheet'!F18,0) -> 5.7095088 | G21: =IF('Balance Sheet'!G18>0,'Profit & Loss'!G4/'Balance Sheet'!G18,0) -> 6.4454063 | H21: =IF('Balance Sheet'!H18>0,'Profit & Loss'!H4/'Balance Sheet'!H18,0) -> 6.2596137 | I21: =IF('Balance Sheet'!I18>0,'Profit & Loss'!I4/'Balance Sheet'!I18,0) -> 5.8849316 | ... K21: =IF('Balance Sheet'!K18>0,'Profit & Loss'!K4/'Balance Sheet'!K18,0) -> 6.3328901
A23: Return on Equity | B23: =IF(SUM('Balance Sheet'!B4:B5)>0,'Profit & Loss'!B12/SUM('Balance Sheet'!B4:B5),"") -> 0.11338635 | C23: =IF(SUM('Balance Sheet'!C4:C5)>0,'Profit & Loss'!C12/SUM('Balance Sheet'!C4:C5),"") -> 0.1229106 | D23: =IF(SUM('Balance Sheet'!D4:D5)>0,'Profit & Loss'!D12/SUM('Balance Sheet'!D4:D5),"") -> 0.10226498 | E23: =IF(SUM('Balance Sheet'!E4:E5)>0,'Profit & Loss'!E12/SUM('Balance Sheet'!E4:E5),"") -> 0.087615714 | F23: =IF(SUM('Balance Sheet'!F4:F5)>0,'Profit & Loss'!F12/SUM('Balance Sheet'!F4:F5),"") -> 0.070165616 | G23: =IF(SUM('Balance Sheet'!G4:G5)>0,'Profit & Loss'!G12/SUM('Balance Sheet'!G4:G5),"") -> 0.077878343 | H23: =IF(SUM('Balance Sheet'!H4:H5)>0,'Profit & Loss'!H12/SUM('Balance Sheet'!H4:H5),"") -> 0.093175875 | I23: =IF(SUM('Balance Sheet'!I4:I5)>0,'Profit & Loss'!I12/SUM('Balance Sheet'!I4:I5),"") -> 0.087741231 | ... K23: =IF(SUM('Balance Sheet'!K4:K5)>0,'Profit & Loss'!K12/SUM('Balance Sheet'!K4:K5),"") -> 0.089349911
A24: Return on Capital Emp | C24: =IF((B4+B5+B6+C4+C5+C6)>0,('Profit & Loss'!C10+'Profit & Loss'!C9)*2/(B4+B5+B6+C4+C5+C6),"") -> 0.11330928 | D24: =IF((C4+C5+C6+D4+D5+D6)>0,('Profit & Loss'!D10+'Profit & Loss'!D9)*2/(C4+C5+C6+D4+D5+D6),"") -> 0.11679443 | E24: =IF((D4+D5+D6+E4+E5+E6)>0,('Profit & Loss'!E10+'Profit & Loss'!E9)*2/(D4+D5+D6+E4+E5+E6),"") -> 0.10090286 | F24: =IF((E4+E5+E6+F4+F5+F6)>0,('Profit & Loss'!F10+'Profit & Loss'!F9)*2/(E4+E5+E6+F4+F5+F6),"") -> 0.085957813 | G24: =IF((F4+F5+F6+G4+G5+G6)>0,('Profit & Loss'!G10+'Profit & Loss'!G9)*2/(F4+F5+F6+G4+G5+G6),"") -> 0.09471565 | H24: =IF((G4+G5+G6+H4+H5+H6)>0,('Profit & Loss'!H10+'Profit & Loss'!H9)*2/(G4+G5+G6+H4+H5+H6),"") -> 0.10064077 | I24: =IF((H4+H5+H6+I4+I5+I6)>0,('Profit & Loss'!I10+'Profit & Loss'!I9)*2/(H4+H5+H6+I4+I5+I6),"") -> 0.11027038 | J24: =IF((I4+I5+I6+J4+J5+J6)>0,('Profit & Loss'!J10+'Profit & Loss'!J9)*2/(I4+I5+I6+J4+J5+J6),"") -> 0.11033178 | K24: =IF((J4+J5+J6+K4+K5+K6)>0,('Profit & Loss'!K10+'Profit & Loss'!K9)*2/(J4+J5+J6+K4+K5+K6),"") -> 0.11924623

Sheet DATAs
D2: ="FIANANCIAL HISTORICAL STATAMENT - "&'Data Sheet'!B1 -> FIANANCIAL HISTORICAL STATAMENT - RELIANCE INDUSTRIES LTD
B3: Years | C3: ='Data Sheet'!B16 -> 42825 | D3: ='Data Sheet'!C16 -> 43190 | E3: ='Data Sheet'!D16 -> 43555 | F3: ='Data Sheet'!E16 -> 43921 | G3: ='Data Sheet'!F16 -> 44286 | H3: ='Data Sheet'!G16 -> 44651 | I3: ='Data Sheet'!H16 -> 45016 | J3: ='Data Sheet'!I16 -> 45382 | ... L3: ='Data Sheet'!K16 -> 46112
A4: # | B4: INCOME STATEMENT
B5: Sales | C5: {=IFERROR('Data Sheet'!B17,'Data Sheet'!B16:K16)} -> 303954 | D5: {=IFERROR('Data Sheet'!C17,'Data Sheet'!C16:L16)} -> 390823 | E5: {=IFERROR('Data Sheet'!D17,'Data Sheet'!D16:M16)} -> 568337 | F5: {=IFERROR('Data Sheet'!E17,'Data Sheet'!E16:N16)} -> 596679 | G5: {=IFERROR('Data Sheet'!F17,'Data Sheet'!F16:O16)} -> 466307 | H5: {=IFERROR('Data Sheet'!G17,'Data Sheet'!G16:P16)} -> 694673 | I5: {=IFERROR('Data Sheet'!H17,'Data Sheet'!H16:Q16)} -> 876396 | J5: {=IFERROR('Data Sheet'!I17,'Data Sheet'!I16:R16)} -> 899041 | ... L5: {=IFERROR('Data Sheet'!K17,'Data Sheet'!K16:T16)} -> 1057219
B6: Sales Growth | D6: =D5/C5-1 -> 0.28579654 | E6: =E5/D5-1 -> 0.45420561 | F6: =F5/E5-1 -> 0.0498683 | G6: =G5/F5-1 -> -0.21849604 | H6: =H5/G5-1 -> 0.48973316 | I6: =I5/H5-1 -> 0.26159502 | J6: =J5/I5-1 -> 0.025838776 | K6: =K5/J5-1 -> 0.070941147 | L6: =L5/K5-1 -> 0.098044287
B8: COGS | C8: =IFERROR(SUM('Data Sheet'!B18,'Data Sheet'!B20:B21,)-1*'Data Sheet'!B19,0) -> 233460 | D8: =IFERROR(SUM('Data Sheet'!C18,'Data Sheet'!C20:C21,)-1*'Data Sheet'!C19,0) -> 291726 | E8: =IFERROR(SUM('Data Sheet'!D18,'Data Sheet'!D20:D21,)-1*'Data Sheet'!D19,0) -> 423714 | F8: =IFERROR(SUM('Data Sheet'!E18,'Data Sheet'!E20:E21,)-1*'Data Sheet'!E19,0) -> 431772 | G8: =IFERROR(SUM('Data Sheet'!F18,'Data Sheet'!F20:F21,)-1*'Data Sheet'!F19,0) -> 313602 | H8: =IFERROR(SUM('Data Sheet'!G18,'Data Sheet'!G20:G21,)-1*'Data Sheet'!G19,0) -> 503068 | I8: =IFERROR(SUM('Data Sheet'!H18,'Data Sheet'!H20:H21,)-1*'Data Sheet'!H19,0) -> 633203 | J8: =IFERROR(SUM('Data Sheet'!I18,'Data Sheet'!I20:I21,)-1*'Data Sheet'!I19,0) -> 625756 | ... L8: =IFERROR(SUM('Data Sheet'!K18,'Data Sheet'!K20:K21,)-1*'Data Sheet'!K19,0) -> 688663
B9: COGS % Sales | C9: =C8/C5 -> 0.76807675 | D9: =D8/D5 -> 0.7464402 | E9: =E8/E5 -> 0.74553302 | F9: =F8/F5 -> 0.72362527 | G9: =G8/G5 -> 0.67252261 | H9: =H8/H5 -> 0.72417958 | I9: =I8/I5 -> 0.72250786 | J9: =J8/J5 -> 0.6960261 | ... L9: =L8/L5 -> 0.65139106
B12: Growth profit | C12: =C5-C8 -> 70494 | D12: =D5-D8 -> 99097 | E12: =E5-E8 -> 144623 | F12: =F5-F8 -> 164907 | G12: =G5-G8 -> 152705 | H12: =H5-H8 -> 191605 | I12: =I5-I8 -> 243193 | J12: =J5-J8 -> 273285 | ... L12: =L5-L8 -> 368556
B13: Growth Margin | C13: =C12/C5 -> 0.23192325 | D13: =D12/D5 -> 0.2535598 | E13: =E12/E5 -> 0.25446698 | F13: =F12/F5 -> 0.27637473 | G13: =G12/G5 -> 0.32747739 | H13: =H12/H5 -> 0.27582042 | I13: =I12/I5 -> 0.27749214 | J13: =J12/J5 -> 0.3039739 | ... L13: =L12/L5 -> 0.34860894
B15: SELLING & GENERAL EXPENSES | C15: =IFERROR(SUM('Data Sheet'!B23,'Data Sheet'!B24),0) -> 15799 | D15: =IFERROR(SUM('Data Sheet'!C23,'Data Sheet'!C24),0) -> 25259 | E15: =IFERROR(SUM('Data Sheet'!D23,'Data Sheet'!D24),0) -> 47885 | F15: =IFERROR(SUM('Data Sheet'!E23,'Data Sheet'!E24),0) -> 61566 | G15: =IFERROR(SUM('Data Sheet'!F23,'Data Sheet'!F24),0) -> 57098 | H15: =IFERROR(SUM('Data Sheet'!G23,'Data Sheet'!G24),0) -> 64266 | I15: =IFERROR(SUM('Data Sheet'!H23,'Data Sheet'!H24),0) -> 76003 | J15: =IFERROR(SUM('Data Sheet'!I23,'Data Sheet'!I24),0) -> 85108 | ... L15: =IFERROR(SUM('Data Sheet'!K23,'Data Sheet'!K24),0) -> 159289
B16: S & G Exp % Sales | C16: =C15/C5 -> 0.05197826 | D16: =D15/D5 -> 0.06463028 | E16: =E15/E5 -> 0.084254588 | F16: =F15/F5 -> 0.10318111 | G16: =G15/G5 -> 0.12244723 | H16: =H15/H5 -> 0.092512592 | I16: =I15/I5 -> 0.086722212 | J16: =J15/J5 -> 0.094665316 | ... L16: =L15/L5 -> 0.15066793
B18: EBITDA | C18: =C12-C15 -> 54695 | D18: =D12-D15 -> 73838 | E18: =E12-E15 -> 96738 | F18: =F12-F15 -> 103341 | G18: =G12-G15 -> 95607 | H18: =H12-H15 -> 127339 | I18: =I12-I15 -> 167190 | J18: =J12-J15 -> 188177 | ... L18: =L12-L15 -> 209267
B19: EBITDA % margins | C19: =C18/C5 -> 0.17994499 | D19: =D18/D5 -> 0.18892952 | E19: =E18/E5 -> 0.17021239 | F19: =F18/F5 -> 0.17319363 | G19: =G18/G5 -> 0.20503016 | H19: =H18/H5 -> 0.18330783 | I19: =I18/I5 -> 0.19076993 | J19: =J18/J5 -> 0.20930859 | ... L19: =L18/L5 -> 0.19794101
B21: Interest | C21: =IFERROR(SUM('Data Sheet'!B27),0) -> 3849 | D21: =IFERROR(SUM('Data Sheet'!C27),0) -> 8052 | E21: =IFERROR(SUM('Data Sheet'!D27),0) -> 16495 | F21: =IFERROR(SUM('Data Sheet'!E27),0) -> 22027 | G21: =IFERROR(SUM('Data Sheet'!F27),0) -> 21189 | H21: =IFERROR(SUM('Data Sheet'!G27),0) -> 14584 | I21: =IFERROR(SUM('Data Sheet'!H27),0) -> 19571 | J21: =IFERROR(SUM('Data Sheet'!I27),0) -> 23118 | ... L21: =IFERROR(SUM('Data Sheet'!K27),0) -> 27061
B22: interest % sales | C22: =C21/C5 -> 0.0126631 | D22: =D21/D5 -> 0.020602677 | E22: =E21/E5 -> 0.029023273 | F22: =F21/F5 -> 0.036915997 | G22: =G21/G5 -> 0.045440021 | H22: =H21/H5 -> 0.02099405 | I22: =I21/I5 -> 0.022331229 | J22: =J21/J5 -> 0.025714066 | ... L22: =L21/L5 -> 0.0255964
B24: DEPRICIATION | C24: =IFERROR(SUM('Data Sheet'!B26),0) -> 11646 | D24: =IFERROR(SUM('Data Sheet'!C26),0) -> 16706 | E24: =IFERROR(SUM('Data Sheet'!D26),0) -> 20934 | F24: =IFERROR(SUM('Data Sheet'!E26),0) -> 22203 | G24: =IFERROR(SUM('Data Sheet'!F26),0) -> 26572 | H24: =IFERROR(SUM('Data Sheet'!G26),0) -> 29782 | I24: =IFERROR(SUM('Data Sheet'!H26),0) -> 40303 | J24: =IFERROR(SUM('Data Sheet'!I26),0) -> 50832 | ... L24: =IFERROR(SUM('Data Sheet'!K26),0) -> 57688
B25: Depriciation % sales | C25: =C24/C5 -> 0.038315008 | D25: =D24/D5 -> 0.042745693 | E25: =E24/E5 -> 0.03683378 | F25: =F24/F5 -> 0.037210963 | G25: =G24/G5 -> 0.056983918 | H25: =H24/H5 -> 0.04287197 | I25: =I24/I5 -> 0.045987202 | J25: =J24/J5 -> 0.056540247 | ... L25: =L24/L5 -> 0.0545658
B27: EARNING BEFORE TAX | C27: =IFERROR(C18-SUM(C21,C24),0) -> 39200 | D27: =IFERROR(D18-SUM(D21,D24),0) -> 49080 | E27: =IFERROR(E18-SUM(E21,E24),0) -> 59309 | F27: =IFERROR(F18-SUM(F21,F24),0) -> 59111 | G27: =IFERROR(G18-SUM(G21,G24),0) -> 47846 | H27: =IFERROR(H18-SUM(H21,H24),0) -> 82973 | I27: =IFERROR(I18-SUM(I21,I24),0) -> 107316 | J27: =IFERROR(J18-SUM(J21,J24),0) -> 114227 | ... L27: =IFERROR(L18-SUM(L21,L24),0) -> 124518
B28: EBT % SALES | C28: =C27/C5 -> 0.12896688 | D28: =D27/D5 -> 0.12558115 | E28: =E27/E5 -> 0.10435534 | F28: =F27/F5 -> 0.099066667 | G28: =G27/G5 -> 0.10260622 | H28: =H27/H5 -> 0.11944181 | I28: =I27/I5 -> 0.12245149 | J28: =J27/J5 -> 0.12705427 | ... L28: =L27/L5 -> 0.11777881
B30: TAX | C30: =IFERROR(SUM('Data Sheet'!B29),0) -> 10201 | D30: =IFERROR(SUM('Data Sheet'!C29),0) -> 13346 | E30: =IFERROR(SUM('Data Sheet'!D29),0) -> 15390 | F30: =IFERROR(SUM('Data Sheet'!E29),0) -> 13726 | G30: =IFERROR(SUM('Data Sheet'!F29),0) -> 1722 | H30: =IFERROR(SUM('Data Sheet'!G29),0) -> 15970 | I30: =IFERROR(SUM('Data Sheet'!H29),0) -> 20376 | J30: =IFERROR(SUM('Data Sheet'!I29),0) -> 25707 | ... L30: =IFERROR(SUM('Data Sheet'!K29),0) -> 27552
B31: Tax % sales | C31: =C30/C5 -> 0.033560999 | D31: =D30/D5 -> 0.034148451 | E31: =E30/E5 -> 0.027079004 | F31: =F30/F5 -> 0.023003994 | G31: =G30/G5 -> 0.0036928461 | H31: =H30/H5 -> 0.022989234 | I31: =I30/I5 -> 0.023249764 | J31: =J30/J5 -> 0.028593802 | ... L31: =L30/L5 -> 0.026060826
B34: NET PROFIT | C34: =D27-D30 -> 35734 | D34: =E27-E30 -> 43919 | E34: =F27-F30 -> 45385 | F34: =G27-G30 -> 46124 | G34: =H27-H30 -> 67003 | H34: =I27-I30 -> 86940 | I34: =J27-J30 -> 88520 | J34: =K27-K30 -> 91522 | ... L34: =M27-M30 -> 0
B35: Net % margin | C35: =C34/C5 -> 0.11756384 | D35: =D34/D5 -> 0.11237568 | E35: =E34/E5 -> 0.07985579 | F35: =F34/F5 -> 0.077301195 | G35: =G34/G5 -> 0.1436886 | H35: =H34/H5 -> 0.12515241 | I35: =I34/I5 -> 0.10100457 | J35: =J34/J5 -> 0.10179958 | ... L35: =L34/L5 -> 0
B39: NO OF EQUTY SHARES | C39: =IFERROR('Data Sheet'!B93,0) -> 1387.22 | D39: =IFERROR('Data Sheet'!C93,0) -> 1351.39 | E39: =IFERROR('Data Sheet'!D93,0) -> 1352.26 | F39: =IFERROR('Data Sheet'!E93,0) -> 1352.37 | G39: =IFERROR('Data Sheet'!F93,0) -> 1267.89 | H39: =IFERROR('Data Sheet'!G93,0) -> 1352.98 | I39: =IFERROR('Data Sheet'!H93,0) -> 1353.12 | J39: =IFERROR('Data Sheet'!I93,0) -> 1353.14 | ... L39: =IFERROR('Data Sheet'!K93,0) -> 1353.25
B41: EARNING PER SHARE | C41: =IFERROR(C34/C39,0) -> 25.759433 | D41: =IFERROR(D34/D39,0) -> 32.499131 | E41: =IFERROR(E34/E39,0) -> 33.562333 | F41: =IFERROR(F34/F39,0) -> 34.106051 | G41: =IFERROR(G34/G39,0) -> 52.846067 | H41: =IFERROR(H34/H39,0) -> 64.258156 | I41: =IFERROR(I34/I39,0) -> 65.419179 | J41: =IFERROR(J34/J39,0) -> 67.636756 | ... L41: =IFERROR(L34/L39,0) -> 0
B43: DIVIDENT PER SHARE | C43: =IFERROR('Data Sheet'!B31/DATAs!C39,0) -> 2.3463474 | D43: =IFERROR('Data Sheet'!C31/DATAs!D39,0) -> 2.6292928 | E43: =IFERROR('Data Sheet'!D31/DATAs!E39,0) -> 2.8484907 | F43: =IFERROR('Data Sheet'!E31/DATAs!F39,0) -> 3.0467624 | G43: =IFERROR('Data Sheet'!F31/DATAs!G39,0) -> 3.558274 | H43: =IFERROR('Data Sheet'!G31/DATAs!H39,0) -> 4.0000591 | I43: =IFERROR('Data Sheet'!H31/DATAs!I39,0) -> 4.5002661 | J43: =IFERROR('Data Sheet'!I31/DATAs!J39,0) -> 5.0002217 | ... L43: =IFERROR('Data Sheet'!K31/DATAs!L39,0) -> 5.9997783
B45: DIVIDENT PAY OUT RATIO | C45: =IFERROR(C43/C41,) -> 0.09108692 | D45: =IFERROR(D43/D41,) -> 0.080903481 | E45: =IFERROR(E43/E41,) -> 0.084871654 | F45: =IFERROR(F43/F41,) -> 0.089332018 | G45: =IFERROR(G43/G41,) -> 0.067332806 | H45: =IFERROR(H43/H41,) -> 0.062249827 | I45: =IFERROR(I43/I41,) -> 0.068791234 | J45: =IFERROR(J43/J41,) -> 0.07392758 | ... L45: =IFERROR(L43/L41,) -> 0
B48: RETAINED EARNING | C48: =IFERROR(1-C45,) -> 0.90891308 | D48: =IFERROR(1-D45,) -> 0.91909652 | E48: =IFERROR(1-E45,) -> 0.91512835 | F48: =IFERROR(1-F45,) -> 0.91066798 | G48: =IFERROR(1-G45,) -> 0.93266719 | H48: =IFERROR(1-H45,) -> 0.93775017 | I48: =IFERROR(1-I45,) -> 0.93120877 | J48: =IFERROR(1-J45,) -> 0.92607242 | ... L48: =IFERROR(1-L45,) -> 1
A51: # | B51: BALANCE SHEET
B53: EQUITY SHARE CAPITAL | C53: =IFERROR('Data Sheet'!B57,0) -> 2959 | D53: =IFERROR('Data Sheet'!C57,0) -> 5922 | E53: =IFERROR('Data Sheet'!D57,0) -> 5926 | F53: =IFERROR('Data Sheet'!E57,0) -> 6339 | G53: =IFERROR('Data Sheet'!F57,0) -> 6445 | H53: =IFERROR('Data Sheet'!G57,0) -> 6765 | I53: =IFERROR('Data Sheet'!H57,0) -> 6766 | J53: =IFERROR('Data Sheet'!I57,0) -> 6766 | ... L53: =IFERROR('Data Sheet'!K57,0) -> 13532
B54: RESERVES | C54: =IFERROR('Data Sheet'!B58,0) -> 260750 | D54: =IFERROR('Data Sheet'!C58,0) -> 287584 | E54: =IFERROR('Data Sheet'!D58,0) -> 381186 | F54: =IFERROR('Data Sheet'!E58,0) -> 442827 | G54: =IFERROR('Data Sheet'!F58,0) -> 693727 | H54: =IFERROR('Data Sheet'!G58,0) -> 772720 | I54: =IFERROR('Data Sheet'!H58,0) -> 709106 | J54: =IFERROR('Data Sheet'!I58,0) -> 786715 | ... L54: =IFERROR('Data Sheet'!K58,0) -> 890498
B55: BORROWING | C55: =IFERROR('Data Sheet'!B59,0) -> 217475 | D55: =IFERROR('Data Sheet'!C59,0) -> 239843 | E55: =IFERROR('Data Sheet'!D59,0) -> 307714 | F55: =IFERROR('Data Sheet'!E59,0) -> 355133 | G55: =IFERROR('Data Sheet'!F59,0) -> 278962 | H55: =IFERROR('Data Sheet'!G59,0) -> 319158 | I55: =IFERROR('Data Sheet'!H59,0) -> 451664 | J55: =IFERROR('Data Sheet'!I59,0) -> 350719 | ... L55: =IFERROR('Data Sheet'!K59,0) -> 398000
B56: OTHER EXPENSES | C56: =IFERROR('Data Sheet'!B60,0) -> 225618 | D56: =IFERROR('Data Sheet'!C60,0) -> 277924 | E56: =IFERROR('Data Sheet'!D60,0) -> 302804 | F56: =IFERROR('Data Sheet'!E60,0) -> 358716 | G56: =IFERROR('Data Sheet'!F60,0) -> 340931 | H56: =IFERROR('Data Sheet'!G60,0) -> 399979 | I56: =IFERROR('Data Sheet'!H60,0) -> 438346 | J56: =IFERROR('Data Sheet'!I60,0) -> 610848 | ... L56: =IFERROR('Data Sheet'!K60,0) -> 876110
B57: TOTAL LIABILITIES | C57: =IFERROR('Data Sheet'!B61,0) -> 706802 | D57: =IFERROR('Data Sheet'!C61,0) -> 811273 | E57: =IFERROR('Data Sheet'!D61,0) -> 997630 | F57: =IFERROR('Data Sheet'!E61,0) -> 1163015 | G57: =IFERROR('Data Sheet'!F61,0) -> 1320065 | H57: =IFERROR('Data Sheet'!G61,0) -> 1498622 | I57: =IFERROR('Data Sheet'!H61,0) -> 1605882 | J57: =IFERROR('Data Sheet'!I61,0) -> 1755048 | ... L57: =IFERROR('Data Sheet'!K61,0) -> 2178140
B60: FIXET ASSET AND BLOCK | C60: =IFERROR('Data Sheet'!B62,0) -> 198526 | D60: =IFERROR('Data Sheet'!C62,0) -> 403885 | E60: =IFERROR('Data Sheet'!D62,0) -> 398374 | F60: =IFERROR('Data Sheet'!E62,0) -> 532658 | G60: =IFERROR('Data Sheet'!F62,0) -> 541258 | H60: =IFERROR('Data Sheet'!G62,0) -> 627798 | I60: =IFERROR('Data Sheet'!H62,0) -> 724805 | J60: =IFERROR('Data Sheet'!I62,0) -> 779985 | ... L60: =IFERROR('Data Sheet'!K62,0) -> 1170194
B61: CAPITAL WORK IN PROGRAMS | C61: =IFERROR('Data Sheet'!B63,0) -> 324837 | D61: =IFERROR('Data Sheet'!C63,0) -> 187022 | E61: =IFERROR('Data Sheet'!D63,0) -> 179463 | F61: =IFERROR('Data Sheet'!E63,0) -> 109106 | G61: =IFERROR('Data Sheet'!F63,0) -> 125953 | H61: =IFERROR('Data Sheet'!G63,0) -> 172506 | I61: =IFERROR('Data Sheet'!H63,0) -> 293752 | J61: =IFERROR('Data Sheet'!I63,0) -> 338855 | ... L61: =IFERROR('Data Sheet'!K63,0) -> 192287
B62: INVESTMENT | C62: =IFERROR('Data Sheet'!B64,0) -> 82899 | D62: =IFERROR('Data Sheet'!C64,0) -> 82862 | E62: =IFERROR('Data Sheet'!D64,0) -> 235635 | F62: =IFERROR('Data Sheet'!E64,0) -> 276767 | G62: =IFERROR('Data Sheet'!F64,0) -> 364828 | H62: =IFERROR('Data Sheet'!G64,0) -> 394264 | I62: =IFERROR('Data Sheet'!H64,0) -> 235560 | J62: =IFERROR('Data Sheet'!I64,0) -> 225672 | ... L62: =IFERROR('Data Sheet'!K64,0) -> 248332
B63: OTHER ASSET | C63: =IFERROR('Data Sheet'!B65-SUM('Data Sheet'!B67:B69),0) -> 40389 | D63: =IFERROR('Data Sheet'!C65-SUM('Data Sheet'!C67:C69),0) -> 54857 | E63: =IFERROR('Data Sheet'!D65-SUM('Data Sheet'!D67:D69),0) -> 75427 | F63: =IFERROR('Data Sheet'!E65-SUM('Data Sheet'!E67:E69),0) -> 120005 | G63: =IFERROR('Data Sheet'!F65-SUM('Data Sheet'!F67:F69),0) -> 169943 | H63: =IFERROR('Data Sheet'!G65-SUM('Data Sheet'!G67:G69),0) -> 136458 | I63: =IFERROR('Data Sheet'!H65-SUM('Data Sheet'!H67:H69),0) -> 114645 | J63: =IFERROR('Data Sheet'!I65-SUM('Data Sheet'!I67:I69),0) -> 128913 | ... L63: =IFERROR('Data Sheet'!K65-SUM('Data Sheet'!K67:K69),0) -> 195918
B64: TOTAL NON CURRENT ASSETS | C64: =SUM(C60:C63) -> 646651 | D64: =SUM(D60:D63) -> 728626 | E64: =SUM(E60:E63) -> 888899 | F64: =SUM(F60:F63) -> 1038536 | G64: =SUM(G60:G63) -> 1201982 | H64: =SUM(H60:H63) -> 1331026 | I64: =SUM(I60:I63) -> 1368762 | J64: =SUM(J60:J63) -> 1473425 | ... L64: =SUM(L60:L63) -> 1806731
B67: RECEVAIBLES | C67: =IFERROR('Data Sheet'!B67,0) -> 8177 | D67: =IFERROR('Data Sheet'!C67,0) -> 17555 | E67: =IFERROR('Data Sheet'!D67,0) -> 30089 | F67: =IFERROR('Data Sheet'!E67,0) -> 19656 | G67: =IFERROR('Data Sheet'!F67,0) -> 19014 | H67: =IFERROR('Data Sheet'!G67,0) -> 23640 | I67: =IFERROR('Data Sheet'!H67,0) -> 28448 | J67: =IFERROR('Data Sheet'!I67,0) -> 31628 | ... L67: =IFERROR('Data Sheet'!K67,0) -> 58491
...

Sheet Sheet1

Sheet RATIO ANANLYSIS
D1: ="RATIO ANALYSIS - "&'Data Sheet'!B1 -> RATIO ANALYSIS - RELIANCE INDUSTRIES LTD
B2: Years | C2: ='Data Sheet'!B16 -> 42825 | D2: ='Data Sheet'!C16 -> 43190 | E2: ='Data Sheet'!D16 -> 43555 | F2: ='Data Sheet'!E16 -> 43921 | G2: ='Data Sheet'!F16 -> 44286 | H2: ='Data Sheet'!G16 -> 44651 | I2: ='Data Sheet'!H16 -> 45016 | J2: ='Data Sheet'!I16 -> 45382 | ... L2: ='Data Sheet'!K16 -> 46112 | M2: Trend | N2: Mean | O2: Median
B4: Sales Growth | C4: =IFERROR(DATAs!C6,0) -> 0 | D4: =IFERROR(DATAs!D6,0) -> 0.28579654 | E4: =IFERROR(DATAs!E6,0) -> 0.45420561 | F4: =IFERROR(DATAs!F6,0) -> 0.0498683 | G4: =IFERROR(DATAs!G6,0) -> -0.21849604 | H4: =IFERROR(DATAs!H6,0) -> 0.48973316 | I4: =IFERROR(DATAs!I6,0) -> 0.26159502 | J4: =IFERROR(DATAs!J6,0) -> 0.025838776 | ... L4: =IFERROR(DATAs!L6,0) -> 0.098044287 | N4: =IFERROR(AVERAGE(C4:L4),0) -> 0.15175268 | O4: =IFERROR(MEDIAN(C4:L4),0) -> 0.084492717
B5: EBIDTA Growth | D5: =IFERROR(DATAs!D18/DATAs!C18-1,0) -> 0.34999543 | E5: =IFERROR(DATAs!E18/DATAs!D18-1,0) -> 0.31013841 | F5: =IFERROR(DATAs!F18/DATAs!E18-1,0) -> 0.068256528 | G5: =IFERROR(DATAs!G18/DATAs!F18-1,0) -> -0.074839609 | H5: =IFERROR(DATAs!H18/DATAs!G18-1,0) -> 0.33190038 | I5: =IFERROR(DATAs!I18/DATAs!H18-1,0) -> 0.31295204 | J5: =IFERROR(DATAs!J18/DATAs!I18-1,0) -> 0.12552784 | K5: =IFERROR(DATAs!K18/DATAs!J18-1,0) -> 0.031778591 | L5: =IFERROR(DATAs!L18/DATAs!K18-1,0) -> 0.077823617 | N5: =IFERROR(AVERAGE(C5:L5),0) -> 0.17039258 | O5: =IFERROR(MEDIAN(C5:L5),0) -> 0.12552784
B6: EBT Growth | D6: =IFERROR(DATAs!D27/DATAs!C27-1,0) -> 0.25204082 | E6: =IFERROR(DATAs!E27/DATAs!D27-1,0) -> 0.20841483 | F6: =IFERROR(DATAs!F27/DATAs!E27-1,0) -> -0.0033384478 | G6: =IFERROR(DATAs!G27/DATAs!F27-1,0) -> -0.19057367 | H6: =IFERROR(DATAs!H27/DATAs!G27-1,0) -> 0.73416796 | I6: =IFERROR(DATAs!I27/DATAs!H27-1,0) -> 0.29338459 | J6: =IFERROR(DATAs!J27/DATAs!I27-1,0) -> 0.064398599 | K6: =IFERROR(DATAs!K27/DATAs!J27-1,0) -> 0.022105106 | L6: =IFERROR(DATAs!L27/DATAs!K27-1,0) -> 0.066517062 | N6: =IFERROR(AVERAGE(C6:L6),0) -> 0.16079076 | O6: =IFERROR(MEDIAN(C6:L6),0) -> 0.066517062
B7: Net Profit Growth | D7: =IFERROR(DATAs!D34/DATAs!C34-1,0) -> 0.22905356 | E7: =IFERROR(DATAs!E34/DATAs!D34-1,0) -> 0.033379631 | F7: =IFERROR(DATAs!F34/DATAs!E34-1,0) -> 0.016282913 | G7: =IFERROR(DATAs!G34/DATAs!F34-1,0) -> 0.45267106 | H7: =IFERROR(DATAs!H34/DATAs!G34-1,0) -> 0.29755384 | I7: =IFERROR(DATAs!I34/DATAs!H34-1,0) -> 0.018173453 | J7: =IFERROR(DATAs!J34/DATAs!I34-1,0) -> 0.03391324 | K7: =IFERROR(DATAs!K34/DATAs!J34-1,0) -> 0.059482966 | L7: =IFERROR(DATAs!L34/DATAs!K34-1,0) -> -1 | N7: =IFERROR(AVERAGE(C7:L7),0) -> 0.015612296 | O7: =IFERROR(MEDIAN(C7:L7),0) -> 0.03391324
B8: Divident Growth | D8: =IFERROR(DATAs!D43/DATAs!C43-1,0) -> 0.12058975 | E8: =IFERROR(DATAs!E43/DATAs!D43-1,0) -> 0.083367616 | F8: =IFERROR(DATAs!F43/DATAs!E43-1,0) -> 0.069605871 | G8: =IFERROR(DATAs!G43/DATAs!F43-1,0) -> 0.16788695 | H8: =IFERROR(DATAs!H43/DATAs!G43-1,0) -> 0.12415715 | I8: =IFERROR(DATAs!I43/DATAs!H43-1,0) -> 0.12504988 | J8: =IFERROR(DATAs!J43/DATAs!I43-1,0) -> 0.11109469 | K8: =IFERROR(DATAs!K43/DATAs!J43-1,0) -> 0.099918714 | L8: =IFERROR(DATAs!L43/DATAs!K43-1,0) -> 0.09090103 | N8: =IFERROR(AVERAGE(C8:L8),0) -> 0.11028574 | O8: =IFERROR(MEDIAN(C8:L8),0) -> 0.11109469
B11: Growth Margin | C11: =IFERROR(DATAs!C13,0) -> 0.23192325 | D11: =IFERROR(DATAs!D13,0) -> 0.2535598 | E11: =IFERROR(DATAs!E13,0) -> 0.25446698 | F11: =IFERROR(DATAs!F13,0) -> 0.27637473 | G11: =IFERROR(DATAs!G13,0) -> 0.32747739 | H11: =IFERROR(DATAs!H13,0) -> 0.27582042 | I11: =IFERROR(DATAs!I13,0) -> 0.27749214 | J11: =IFERROR(DATAs!J13,0) -> 0.3039739 | ... L11: =IFERROR(DATAs!L13,0) -> 0.34860894 | N11: =IFERROR(AVERAGE(C11:L11),0) -> 0.28518828 | O11: =IFERROR(MEDIAN(C11:L11),0) -> 0.27693344
B12: EBIDTA Margin | C12: =IFERROR(DATAs!C19,0) -> 0.17994499 | D12: =IFERROR(DATAs!D19,0) -> 0.18892952 | E12: =IFERROR(DATAs!E19,0) -> 0.17021239 | F12: =IFERROR(DATAs!F19,0) -> 0.17319363 | G12: =IFERROR(DATAs!G19,0) -> 0.20503016 | H12: =IFERROR(DATAs!H19,0) -> 0.18330783 | I12: =IFERROR(DATAs!I19,0) -> 0.19076993 | J12: =IFERROR(DATAs!J19,0) -> 0.20930859 | ... L12: =IFERROR(DATAs!L19,0) -> 0.19794101 | N12: =IFERROR(AVERAGE(C12:L12),0) -> 0.19002926 | O12: =IFERROR(MEDIAN(C12:L12),0) -> 0.18984972
B13: EBIT Margin | C13: =IFERROR((DATAs!C18-DATAs!C24)/DATAs!C5,0) -> 0.14162998 | D13: =IFERROR((DATAs!D18-DATAs!D24)/DATAs!D5,0) -> 0.14618382 | E13: =IFERROR((DATAs!E18-DATAs!E24)/DATAs!E5,0) -> 0.13337861 | F13: =IFERROR((DATAs!F18-DATAs!F24)/DATAs!F5,0) -> 0.13598266 | G13: =IFERROR((DATAs!G18-DATAs!G24)/DATAs!G5,0) -> 0.14804624 | H13: =IFERROR((DATAs!H18-DATAs!H24)/DATAs!H5,0) -> 0.14043586 | I13: =IFERROR((DATAs!I18-DATAs!I24)/DATAs!I5,0) -> 0.14478272 | J13: =IFERROR((DATAs!J18-DATAs!J24)/DATAs!J5,0) -> 0.15276834 | ... L13: =IFERROR((DATAs!L18-DATAs!L24)/DATAs!L5,0) -> 0.14337521 | N13: =IFERROR(AVERAGE(C13:L13),0) -> 0.14330501 | O13: =IFERROR(MEDIAN(C13:L13),0) -> 0.14407897
B14: EBT Margin | C14: =IFERROR(DATAs!C28,0) -> 0.12896688 | D14: =IFERROR(DATAs!D28,0) -> 0.12558115 | E14: =IFERROR(DATAs!E28,0) -> 0.10435534 | F14: =IFERROR(DATAs!F28,0) -> 0.099066667 | G14: =IFERROR(DATAs!G28,0) -> 0.10260622 | H14: =IFERROR(DATAs!H28,0) -> 0.11944181 | I14: =IFERROR(DATAs!I28,0) -> 0.12245149 | J14: =IFERROR(DATAs!J28,0) -> 0.12705427 | ... L14: =IFERROR(DATAs!L28,0) -> 0.11777881 | N14: =IFERROR(AVERAGE(C14:L14),0) -> 0.11685631 | O14: =IFERROR(MEDIAN(C14:L14),0) -> 0.12035114
B15: Net profit margin | C15: =IFERROR(DATAs!C35,0) -> 0.11756384 | D15: =IFERROR(DATAs!D35,0) -> 0.11237568 | E15: =IFERROR(DATAs!E35,0) -> 0.07985579 | F15: =IFERROR(DATAs!F35,0) -> 0.077301195 | G15: =IFERROR(DATAs!G35,0) -> 0.1436886 | H15: =IFERROR(DATAs!H35,0) -> 0.12515241 | I15: =IFERROR(DATAs!I35,0) -> 0.10100457 | J15: =IFERROR(DATAs!J35,0) -> 0.10179958 | ... L15: =IFERROR(DATAs!L35,0) -> 0 | N15: =IFERROR(AVERAGE(C15:L15),0) -> 0.095945208 | O15: =IFERROR(MEDIAN(C15:L15),0) -> 0.10140208
B17: Sales expense ratio | C17: =IFERROR(DATAs!C16,0) -> 0.05197826 | D17: =IFERROR(DATAs!D16,0) -> 0.06463028 | E17: =IFERROR(DATAs!E16,0) -> 0.084254588 | F17: =IFERROR(DATAs!F16,0) -> 0.10318111 | G17: =IFERROR(DATAs!G16,0) -> 0.12244723 | H17: =IFERROR(DATAs!H16,0) -> 0.092512592 | I17: =IFERROR(DATAs!I16,0) -> 0.086722212 | J17: =IFERROR(DATAs!J16,0) -> 0.094665316 | ... L17: =IFERROR(DATAs!L16,0) -> 0.15066793 | N17: =IFERROR(AVERAGE(C17:L17),0) -> 0.095159025 | O17: =IFERROR(MEDIAN(C17:L17),0) -> 0.093588954
B18: depreciation % Sales | C18: =IFERROR(DATAs!C25,0) -> 0.038315008 | D18: =IFERROR(DATAs!D25,0) -> 0.042745693 | E18: =IFERROR(DATAs!E25,0) -> 0.03683378 | F18: =IFERROR(DATAs!F25,0) -> 0.037210963 | G18: =IFERROR(DATAs!G25,0) -> 0.056983918 | H18: =IFERROR(DATAs!H25,0) -> 0.04287197 | I18: =IFERROR(DATAs!I25,0) -> 0.045987202 | J18: =IFERROR(DATAs!J25,0) -> 0.056540247 | ... L18: =IFERROR(DATAs!L25,0) -> 0.0545658 | N18: =IFERROR(AVERAGE(C18:L18),0) -> 0.046724247 | O18: =IFERROR(MEDIAN(C18:L18),0) -> 0.044429586
B19: Operating profit % Ratio | C19: ='RATIO ANANLYSIS'!C13 -> 0.14162998 | D19: ='RATIO ANANLYSIS'!D13 -> 0.14618382 | E19: ='RATIO ANANLYSIS'!E13 -> 0.13337861 | F19: ='RATIO ANANLYSIS'!F13 -> 0.13598266 | G19: ='RATIO ANANLYSIS'!G13 -> 0.14804624 | H19: ='RATIO ANANLYSIS'!H13 -> 0.14043586 | I19: ='RATIO ANANLYSIS'!I13 -> 0.14478272 | J19: ='RATIO ANANLYSIS'!J13 -> 0.15276834 | ... L19: ='RATIO ANANLYSIS'!L13 -> 0.14337521 | N19: =IFERROR(AVERAGE(C19:L19),0) -> 0.14330501 | O19: =IFERROR(MEDIAN(C19:L19),0) -> 0.14407897
B21: Return Of Captal Employee | C21: =(DATAs!C18-DATAs!C24)/SUM(DATAs!C53,DATAs!C54,DATAs!C55) -> 0.089464737 | D21: =(DATAs!D18-DATAs!D24)/SUM(DATAs!D53,DATAs!D54,DATAs!D55) -> 0.10711935 | E21: =(DATAs!E18-DATAs!E24)/SUM(DATAs!E53,DATAs!E54,DATAs!E55) -> 0.10909782 | F21: =(DATAs!F18-DATAs!F24)/SUM(DATAs!F53,DATAs!F54,DATAs!F55) -> 0.10088039 | G21: =(DATAs!G18-DATAs!G24)/SUM(DATAs!G53,DATAs!G54,DATAs!G55) -> 0.070506182 | H21: =(DATAs!H18-DATAs!H24)/SUM(DATAs!H53,DATAs!H54,DATAs!H55) -> 0.088797726 | I21: =(DATAs!I18-DATAs!I24)/SUM(DATAs!I53,DATAs!I54,DATAs!I55) -> 0.1086793 | J21: =(DATAs!J18-DATAs!J24)/SUM(DATAs!J53,DATAs!J54,DATAs!J55) -> 0.12003583 | ... L21: =(DATAs!L18-DATAs!L24)/SUM(DATAs!L53,DATAs!L54,DATAs!L55) -> 0.11641744 | N21: =IFERROR(AVERAGE(C21:L21),0) -> 0.10268259 | O21: =IFERROR(MEDIAN(C21:L21),0) -> 0.10789933
B22: Returned Earning % | C22: =IFERROR(DATAs!C48,) -> 0.90891308 | D22: =IFERROR(DATAs!D48,) -> 0.91909652 | E22: =IFERROR(DATAs!E48,) -> 0.91512835 | F22: =IFERROR(DATAs!F48,) -> 0.91066798 | G22: =IFERROR(DATAs!G48,) -> 0.93266719 | H22: =IFERROR(DATAs!H48,) -> 0.93775017 | I22: =IFERROR(DATAs!I48,) -> 0.93120877 | J22: =IFERROR(DATAs!J48,) -> 0.92607242 | ... L22: =IFERROR(DATAs!L48,) -> 1 | N22: =IFERROR(AVERAGE(C22:L22),0) -> 0.93047497 | O22: =IFERROR(MEDIAN(C22:L22),0) -> 0.92465884
B23: Return Of Equity % | C23: =IFERROR(DATAs!C34/SUM(DATAs!C53:C54),0) -> 0.13550542 | D23: =IFERROR(DATAs!D34/SUM(DATAs!D53:D54),0) -> 0.14963578 | E23: =IFERROR(DATAs!E34/SUM(DATAs!E53:E54),0) -> 0.11723997 | F23: =IFERROR(DATAs!F34/SUM(DATAs!F53:F54),0) -> 0.10268809 | G23: =IFERROR(DATAs!G34/SUM(DATAs!G53:G54),0) -> 0.095695058 | H23: =IFERROR(DATAs!H34/SUM(DATAs!H53:H54),0) -> 0.11153518 | I23: =IFERROR(DATAs!I34/SUM(DATAs!I53:I54),0) -> 0.12365339 | J23: =IFERROR(DATAs!J34/SUM(DATAs!J53:J54),0) -> 0.1153424 | ... L23: =IFERROR(DATAs!L34/SUM(DATAs!L53:L54),0) -> 0 | N23: =IFERROR(AVERAGE(C23:L23),0) -> 0.10662929 | O23: =IFERROR(MEDIAN(C23:L23),0) -> 0.11517001
B24: Self Sustained Growth Rate | C24: =IFERROR(C22*C23,0) -> 0.12316265 | D24: =IFERROR(D22*D23,0) -> 0.13752973 | E24: =IFERROR(E22*E23,0) -> 0.10728962 | F24: =IFERROR(F22*F23,0) -> 0.093514758 | G24: =IFERROR(G22*G23,0) -> 0.089251641 | H24: =IFERROR(H22*H23,0) -> 0.10459213 | I24: =IFERROR(I22*I23,0) -> 0.11514712 | J24: =IFERROR(J22*J23,0) -> 0.10681541 | ... L24: =IFERROR(L22*L23,0) -> 0 | N24: =IFERROR(AVERAGE(C24:L24),0) -> 0.098347408 | O24: =IFERROR(MEDIAN(C24:L24),0) -> 0.10649321
B25: Interest Coverage Ratio | C25: =IFERROR((DATAs!C18-DATAs!C24)/DATAs!C21,0) -> 11.184463 | D25: =IFERROR((DATAs!D18-DATAs!D24)/DATAs!D21,0) -> 7.09538 | E25: =IFERROR((DATAs!E18-DATAs!E24)/DATAs!E21,0) -> 4.5955744 | F25: =IFERROR((DATAs!F18-DATAs!F24)/DATAs!F21,0) -> 3.6835702 | G25: =IFERROR((DATAs!G18-DATAs!G24)/DATAs!G21,0) -> 3.2580584 | H25: =IFERROR((DATAs!H18-DATAs!H24)/DATAs!H21,0) -> 6.6893171 | I25: =IFERROR((DATAs!I18-DATAs!I24)/DATAs!I21,0) -> 6.4834193 | J25: =IFERROR((DATAs!J18-DATAs!J24)/DATAs!J21,0) -> 5.9410416 | ... L25: =IFERROR((DATAs!L18-DATAs!L24)/DATAs!L21,0) -> 5.6013821 | N25: =IFERROR(AVERAGE(C25:L25),0) -> 6.0342953 | O25: =IFERROR(MEDIAN(C25:L25),0) -> 5.8758939
B27: Debtor Turnover Ratio | C27: =IFERROR(DATAs!C5/DATAs!C67,0) -> 37.171823 | D27: =IFERROR(DATAs!D5/DATAs!D67,0) -> 22.262774 | E27: =IFERROR(DATAs!E5/DATAs!E67,0) -> 18.888531 | F27: =IFERROR(DATAs!F5/DATAs!F67,0) -> 30.356074 | G27: =IFERROR(DATAs!G5/DATAs!G67,0) -> 24.524403 | H27: =IFERROR(DATAs!H5/DATAs!H67,0) -> 29.385491 | I27: =IFERROR(DATAs!I5/DATAs!I67,0) -> 30.806946 | J27: =IFERROR(DATAs!J5/DATAs!J67,0) -> 28.425477 | ... L27: =IFERROR(DATAs!L5/DATAs!L67,0) -> 18.0749 | N27: =IFERROR(AVERAGE(C27:L27),0) -> 26.275485 | O27: =IFERROR(MEDIAN(C27:L27),0) -> 26.47494
B28: Creditor Turnover Ratio | C28: =IFERROR(DATAs!C5/DATAs!C56,0) -> 1.3472063 | D28: =IFERROR(DATAs!D5/DATAs!D56,0) -> 1.4062226 | E28: =IFERROR(DATAs!E5/DATAs!E56,0) -> 1.8769138 | F28: =IFERROR(DATAs!F5/DATAs!F56,0) -> 1.6633744 | G28: =IFERROR(DATAs!G5/DATAs!G56,0) -> 1.367746 | H28: =IFERROR(DATAs!H5/DATAs!H56,0) -> 1.7367737 | I28: =IFERROR(DATAs!I5/DATAs!I56,0) -> 1.9993247 | J28: =IFERROR(DATAs!J5/DATAs!J56,0) -> 1.4717917 | ... L28: =IFERROR(DATAs!L5/DATAs!L56,0) -> 1.2067195 | N28: =IFERROR(AVERAGE(C28:L28),0) -> 1.5391041 | O28: =IFERROR(MEDIAN(C28:L28),0) -> 1.4390071
B29: Inventory Turnover | C29: =IFERROR(DATAs!C5/DATAs!C68,0) -> 6.2093522 | D29: =IFERROR(DATAs!D5/DATAs!D68,0) -> 6.4241005 | E29: =IFERROR(DATAs!E5/DATAs!E68,0) -> 8.4122053 | F29: =IFERROR(DATAs!F5/DATAs!F68,0) -> 8.073813 | G29: =IFERROR(DATAs!G5/DATAs!G68,0) -> 5.7095088 | H29: =IFERROR(DATAs!H5/DATAs!H68,0) -> 6.4454063 | I29: =IFERROR(DATAs!I5/DATAs!I68,0) -> 6.2596137 | J29: =IFERROR(DATAs!J5/DATAs!J68,0) -> 5.8849316 | ... L29: =IFERROR(DATAs!L5/DATAs!L68,0) -> 6.3328901 | N29: =IFERROR(AVERAGE(C29:L29),0) -> 6.634368 | O29: =IFERROR(MEDIAN(C29:L29),0) -> 6.3784953
B30: Fixed Asset Turnover | C30: =IFERROR(DATAs!C5/DATAs!C60,0) -> 1.5310539 | D30: =IFERROR(DATAs!D5/DATAs!D60,0) -> 0.96765911 | E30: =IFERROR(DATAs!E5/DATAs!E60,0) -> 1.4266418 | F30: =IFERROR(DATAs!F5/DATAs!F60,0) -> 1.1201916 | G30: =IFERROR(DATAs!G5/DATAs!G60,0) -> 0.86152445 | H30: =IFERROR(DATAs!H5/DATAs!H60,0) -> 1.1065231 | I30: =IFERROR(DATAs!I5/DATAs!I60,0) -> 1.2091473 | J30: =IFERROR(DATAs!J5/DATAs!J60,0) -> 1.1526388 | ... L30: =IFERROR(DATAs!L5/DATAs!L60,0) -> 0.90345618 | N30: =IFERROR(AVERAGE(C30:L30),0) -> 1.1242241 | O30: =IFERROR(MEDIAN(C30:L30),0) -> 1.1133573
B31: Capital Turnover | C31: =IFERROR(DATAs!C5/SUM(DATAs!C53:C54),0) -> 1.1526114 | D31: =IFERROR(DATAs!D5/SUM(DATAs!D53:D54),0) -> 1.3315673 | E31: =IFERROR(DATAs!E5/SUM(DATAs!E53:E54),0) -> 1.4681462 | F31: =IFERROR(DATAs!F5/SUM(DATAs!F53:F54),0) -> 1.3284153 | G31: =IFERROR(DATAs!G5/SUM(DATAs!G53:G54),0) -> 0.66598921 | H31: =IFERROR(DATAs!H5/SUM(DATAs!H53:H54),0) -> 0.89119483 | I31: =IFERROR(DATAs!I5/SUM(DATAs!I53:I54),0) -> 1.2242356 | J31: =IFERROR(DATAs!J5/SUM(DATAs!J53:J54),0) -> 1.1330341 | ... L31: =IFERROR(DATAs!L5/SUM(DATAs!L53:L54),0) -> 1.1694512 | N31: =IFERROR(AVERAGE(C31:L31),0) -> 1.150651 | O31: =IFERROR(MEDIAN(C31:L31),0) -> 1.1610313
B33: Debtor Days | C33: =IFERROR(365/C27,0) -> 9.8192654 | D33: =IFERROR(365/D27,0) -> 16.395082 | E33: =IFERROR(365/E27,0) -> 19.323896 | F33: =IFERROR(365/F27,0) -> 12.023953 | G33: =IFERROR(365/G27,0) -> 14.883135 | H33: =IFERROR(365/H27,0) -> 12.421096 | I33: =IFERROR(365/I27,0) -> 11.847977 | J33: =IFERROR(365/J27,0) -> 12.840593 | ... L33: =IFERROR(365/L27,0) -> 20.193749 | N33: =IFERROR(AVERAGE(C33:L33),0) -> 14.57166 | O33: =IFERROR(AVERAGE(D33:M33),0) -> 15.099703
B34: Payable Days | C34: =IFERROR(365/C28,0) -> 270.93103 | D34: =IFERROR(365/D28,0) -> 259.56062 | E34: =IFERROR(365/E28,0) -> 194.46818 | F34: =IFERROR(365/F28,0) -> 219.43346 | G34: =IFERROR(365/G28,0) -> 266.86242 | H34: =IFERROR(365/H28,0) -> 210.15979 | I34: =IFERROR(365/I28,0) -> 182.56164 | J34: =IFERROR(365/J28,0) -> 247.99705 | ... L34: =IFERROR(365/L28,0) -> 302.47295 | N34: =IFERROR(AVERAGE(C34:L34),0) -> 243.20203 | O34: =IFERROR(AVERAGE(D34:M34),0) -> 240.12103
B35: Inventory Days | C35: =IFERROR(365/C29,0) -> 58.782299 | D35: =IFERROR(365/D29,0) -> 56.817293 | E35: =IFERROR(365/E29,0) -> 43.389336 | F35: =IFERROR(365/F29,0) -> 45.207884 | G35: =IFERROR(365/G29,0) -> 63.928442 | H35: =IFERROR(365/H29,0) -> 56.629479 | I35: =IFERROR(365/I29,0) -> 58.310307 | J35: =IFERROR(365/J29,0) -> 62.022811 | ... L35: =IFERROR(365/L29,0) -> 57.635613 | N35: =IFERROR(AVERAGE(C35:L35),0) -> 55.80948 | O35: =IFERROR(AVERAGE(D35:M35),0) -> 55.479167
B36: Cash Conversion Cycle | C36: =IFERROR(C33+C35-C34,0) -> -202.32946 | D36: =IFERROR(D33+D35-D34,0) -> -186.34824 | E36: =IFERROR(E33+E35-E34,0) -> -131.75494 | F36: =IFERROR(F33+F35-F34,0) -> -162.20163 | G36: =IFERROR(G33+G35-G34,0) -> -188.05084 | H36: =IFERROR(H33+H35-H34,0) -> -141.10922 | I36: =IFERROR(I33+I35-I34,0) -> -112.40335 | J36: =IFERROR(J33+J35-J34,0) -> -173.13365 | ... L36: =IFERROR(L33+L35-L34,0) -> -224.64359 | N36: =IFERROR(AVERAGE(C36:L36),0) -> -172.82089 | O36: =IFERROR(AVERAGE(D36:M36),0) -> -169.54216

Sheet FORCASTING
C1: =""
B2: ='Data Sheet'!B1&" - "&'Data Sheet'!A17 -> RELIANCE INDUSTRIES LTD - Sales
B3: Years Wright | C3: Years | D3: Sales | E3: Sales growth | M3: =""
B4: 1 | C4: 2017 | D4: {=TRANSPOSE('Data Sheet'!B17:K17)} -> 303954
B5: 2 | C5: 2018 | D5: 390823 | E5: =D5/D4-1 -> 0.28579654
B6: 3 | C6: 2019 | D6: 568337 | E6: =D6/D5-1 -> 0.45420561
B7: 4 | C7: 2020 | D7: 596679 | E7: =D7/D6-1 -> 0.0498683
B8: 5 | C8: 2021 | D8: 466307 | E8: =D8/D7-1 -> -0.21849604
B9: 6 | C9: 2022 | D9: 694673 | E9: =D9/D8-1 -> 0.48973316
B10: 7 | C10: 2023 | D10: 876396 | E10: =D10/D9-1 -> 0.26159502
B11: 8 | C11: 2024 | D11: 899041 | E11: =D11/D10-1 -> 0.025838776
B12: 9 | C12: 2025 | D12: 962820 | E12: =D12/D11-1 -> 0.070941147
B13: 10 | C13: 2026 | D13: 1057219 | E13: =D13/D12-1 -> 0.098044287
B14: 11 | C14: 2027 | D14: =_xlfn.FORECAST.LINEAR(B14,_xlfn.ANCHORARRAY(D4),B4:B13) -> 1131771.6 | E14: =D14/D13-1 -> 0.070517651
B15: 12 | C15: 2028 | D15: =_xlfn.FORECAST.LINEAR(B15,D4:D14,B4:B14) -> 1213616.5 | E15: =D15/D14-1 -> 0.072315699
B16: 13 | C16: 2029 | D16: =_xlfn.FORECAST.LINEAR(B16,D5:D15,B5:B15) -> 1293246.8 | E16: =D16/D15-1 -> 0.065614099
B17: 14 | C17: 2030 | D17: =_xlfn.FORECAST.LINEAR(B17,D6:D16,B6:B16) -> 1372748.4 | E17: =D17/D16-1 -> 0.061474393
B18: 15 | C18: 2031 | D18: =_xlfn.FORECAST.LINEAR(B18,D7:D17,B7:B17) -> 1473894.3 | E18: =D18/D17-1 -> 0.073681355

Sheet WEIGHTAGE AVARAGE COST METHOD
B2: Weightage Avarege Cost Of Capital
B4: All Figure are in (INR) unlesss Otherwise Started
B6: Peer Comps
G7: Debt/ | H7: Debt/ | I7: leaverd | J7: Unleaverd
B8: Nmes of the Company Country | D8: Total Debt | E8: Total Equity | F8: tax Rate 1 | G8: Equity | H8: Capital | I8: Beta 2 | J8: Beta 3
B10: Hindutan Unileaver | C10: India | D10: 1139 | E10: 611500 | F10: 30 | G10: =D10/E10 -> 0.0018626329 | H10: =D10/SUM(D10,E10) -> 0.0018591699 | I10: 1 | J10: =I10/1+(1-F10)*G10 -> 0.94598365
B11: Nestle india | C11: India | D11: 279 | E11: 183975 | F11: 30 | G11: =D11/E11 -> 0.0015165104 | H11: =D11/SUM(D11,E11) -> 0.0015142141 | I11: 1 | J11: =I11/1+(1-F11)*G11 -> 0.9560212
B12: Godrej Consumer | C12: India | D12: 3017 | E12: 110000 | F12: 30 | G12: =D12/E12 -> 0.027427273 | H12: =D12/SUM(D12,E12) -> 0.026695099 | I12: 1 | J12: =I12/1+(1-F12)*G12 -> 0.20460909
B13: Dabur India | C13: India | D13: 1164 | E13: 93546 | F13: 30 | G13: =D13/E13 -> 0.012443076 | H13: =D13/SUM(D13,E13) -> 0.012290149 | I13: 1 | J13: =I13/1+(1-F13)*G13 -> 0.63915079
B14: Britania India | C14: India | D14: 1064 | E14: 94805 | F14: 30 | G14: =D14/E14 -> 0.011223037 | H14: =D14/SUM(D14,E14) -> 0.011098478 | I14: 1 | J14: =I14/1+(1-F14)*G14 -> 0.67453193
E16: Avarage | F16: =AVERAGE(F10:F14) -> 30 | G16: =AVERAGE(G10:G14) -> 0.010894506 | H16: =AVERAGE(H10:H14) -> 0.010691422 | I16: =AVERAGE(I10:I14) -> 1 | J16: =AVERAGE(J10:J14) -> 0.68405933
E17: Median | F17: =MEDIAN(F10:F14) -> 30 | G17: =MEDIAN(G10:G14) -> 0.011223037 | H17: =MEDIAN(H10:H14) -> 0.011098478 | I17: =MEDIAN(I10:I14) -> 1 | J17: =MEDIAN(J10:J14) -> 0.67453193
B20: Cost Of Debt | I20: Cost Of Equity
B22: pre Tax Cost of Debt | D22: 8.4 | I22: Risk Free Rate | N22: 0.065
B23: Tax Rate | D23: 0.3 | I23: Equity Risk Premium | N23: 0.08
B24: Profit tax Cost of Debt | D24: =D22*(1-D23) -> 5.88 | I24: Leaverd Beta 4 | N24: =N35 -> 1.0235289
I25: Cost of Equity | N25: =N22+N23*N24 -> 0.14688231
B30: Capital structure | I30: Leavered Beta
I32: Comp Median Unleaverded Beta | N32: =J17 -> 0.67453193
E33: Current | F33: Target | I33: Target Debt/Equity | N33: =F38 -> 0.73913043
B34: Total Debt | D34: 15000 | E34: =D34/D36 -> 0.33333333 | F34: 0.425 | I34: Tax rate | N34: =D23 -> 0.3
B35: Market Capitalisation | D35: 30000 | E35: =D35/D36 -> 0.66666667 | F35: =F36-F34 -> 0.575 | I35: Leavered Beta | N35: =N32*(1+(1-N34)*N33) -> 1.0235289
B36: Total Capital | D36: =D35+D34 -> 45000 | E36: 1 | F36: 1
B38: Debt/Equity | E38: =E34/E35 -> 0.5 | F38: =F34/F35 -> 0.73913043 | I38: Weighted Avarage Cost of Capital
M41: Total Cost | N41: Total Weight
I42: Debt | M42: 0.0588 | N42: =F34 -> 0.425
I43: Equity | M43: =N25 -> 0.14688231 | N43: =F35 -> 0.575
I44: Weighted Avarage Cost of Capital | N44: =SUMPRODUCT(M42:M43,N42:N43) -> 0.10944733
